Exception in thread django-main-thread:
Traceback (most recent call last):
  File "/usr/lib64/python3.12/threading.py", line 1075, in _bootstrap_inner
    self.run()
  File "/usr/lib64/python3.12/threading.py", line 1012, in run
    self._target(*self._args, **self._kwargs)
  File "/home/xpolas/banska/skj/repos/.venv/lib/python3.12/site-packages/django/utils/autoreload.py", line 64, in wrapper
    fn(*args, **kwargs)
  File "/home/xpolas/banska/skj/repos/.venv/lib/python3.12/site-packages/django/core/management/commands/runserver.py", line 134, in inner_run
    self.check(**check_kwargs)
  File "/home/xpolas/banska/skj/repos/.venv/lib/python3.12/site-packages/django/core/management/base.py", line 492, in check
    all_issues = checks.run_checks(
                 ^^^^^^^^^^^^^^^^^^
  File "/home/xpolas/banska/skj/repos/.venv/lib/python3.12/site-packages/django/core/checks/registry.py", line 89, in run_checks
    new_errors = check(app_configs=app_configs, databases=databases)
                 ^^^^^^^^^^^^^^^^^^^^^^^^^^^^^^^^^^^^^^^^^^^^^^^^^^^
  File "/home/xpolas/banska/skj/repos/.venv/lib/python3.12/site-packages/django/core/checks/urls.py", line 136, in check_custom_error_handlers
    handler = resolver.resolve_error_handler(status_code)
              ^^^^^^^^^^^^^^^^^^^^^^^^^^^^^^^^^^^^^^^^^^^
  File "/home/xpolas/banska/skj/repos/.venv/lib/python3.12/site-packages/django/urls/resolvers.py", line 732, in resolve_error_handler
    callback = getattr(self.urlconf_module, "handler%s" % view_type, None)
                       ^^^^^^^^^^^^^^^^^^^
  File "/home/xpolas/banska/skj/repos/.venv/lib/python3.12/site-packages/django/utils/functional.py", line 47, in __get__
    res = instance.__dict__[self.name] = self.func(instance)
                                         ^^^^^^^^^^^^^^^^^^^
  File "/home/xpolas/banska/skj/repos/.venv/lib/python3.12/site-packages/django/urls/resolvers.py", line 711, in urlconf_module
    return import_module(self.urlconf_name)
           ^^^^^^^^^^^^^^^^^^^^^^^^^^^^^^^^
  File "/usr/lib64/python3.12/importlib/__init__.py", line 90, in import_module
    return _bootstrap._gcd_import(name[level:], package, level)
           ^^^^^^^^^^^^^^^^^^^^^^^^^^^^^^^^^^^^^^^^^^^^^^^^^^^^
  File "<frozen importlib._bootstrap>", line 1387, in _gcd_import
  File "<frozen importlib._bootstrap>", line 1360, in _find_and_load
  File "<frozen importlib._bootstrap>", line 1331, in _find_and_load_unlocked
  File "<frozen importlib._bootstrap>", line 935, in _load_unlocked
  File "<frozen importlib._bootstrap_external>", line 999, in exec_module
  File "<frozen importlib._bootstrap>", line 488, in _call_with_frames_removed
  File "/home/xpolas/banska/skj/repos/repos/urls.py", line 2, in <module>
    from repos_app import views as repo_views
  File "/home/xpolas/banska/skj/repos/repos_app/views.py", line 4, in <module>
    from repos_app.forms import (CommitForm,
  File "/home/xpolas/banska/skj/repos/repos_app/forms.py", line 42, in <module>
    class PullRequestForm(forms.ModelForm):
  File "/home/xpolas/banska/skj/repos/.venv/lib/python3.12/site-packages/django/forms/models.py", line 334, in __new__
    raise FieldError(message)
django.core.exceptions.FieldError: Unknown field(s) (labels) specified for PullRequest
